Traceback (most recent call last):
  File "/home/runner/work/traces-sklearn/traces-sklearn/.pixi/envs/docs/lib/python3.12/site-packages/jupyter_cache/executors/utils.py", line 58, in single_nb_execution
    executenb(
  File "/home/runner/work/traces-sklearn/traces-sklearn/.pixi/envs/docs/lib/python3.12/site-packages/nbclient/client.py", line 1314, in execute
    return NotebookClient(nb=nb, resources=resources, km=km, **kwargs).execute()
           ^^^^^^^^^^^^^^^^^^^^^^^^^^^^^^^^^^^^^^^^^^^^^^^^^^^^^^^^^^^^^^^^^^^^^
  File "/home/runner/work/traces-sklearn/traces-sklearn/.pixi/envs/docs/lib/python3.12/site-packages/jupyter_core/utils/__init__.py", line 165, in wrapped
    return loop.run_until_complete(inner)
           ^^^^^^^^^^^^^^^^^^^^^^^^^^^^^^
  File "/home/runner/work/traces-sklearn/traces-sklearn/.pixi/envs/docs/lib/python3.12/asyncio/base_events.py", line 687, in run_until_complete
    return future.result()
           ^^^^^^^^^^^^^^^
  File "/home/runner/work/traces-sklearn/traces-sklearn/.pixi/envs/docs/lib/python3.12/site-packages/nbclient/client.py", line 709, in async_execute
    await self.async_execute_cell(
  File "/home/runner/work/traces-sklearn/traces-sklearn/.pixi/envs/docs/lib/python3.12/site-packages/nbclient/client.py", line 1062, in async_execute_cell
    await self._check_raise_for_error(cell, cell_index, exec_reply)
  File "/home/runner/work/traces-sklearn/traces-sklearn/.pixi/envs/docs/lib/python3.12/site-packages/nbclient/client.py", line 918, in _check_raise_for_error
    raise CellExecutionError.from_cell_and_msg(cell, exec_reply_content)
nbclient.exceptions.CellExecutionError: An error occurred while executing the following cell:
------------------
ensemble_weight = [
    (y.size - mask_misclassified.sum()) / y.size,
    (y.size - mask_new_misclassifier.sum()) / y.size,
]
ensemble_weight
------------------


[0;31m---------------------------------------------------------------------------[0m
[0;31mNameError[0m                                 Traceback (most recent call last)
Cell [0;32mIn[9], line 3[0m
[1;32m      1[0m ensemble_weight [38;5;241m=[39m [
[1;32m      2[0m     (y[38;5;241m.[39msize [38;5;241m-[39m mask_misclassified[38;5;241m.[39msum()) [38;5;241m/[39m y[38;5;241m.[39msize,
[0;32m----> 3[0m     (y[38;5;241m.[39msize [38;5;241m-[39m [43mmask_new_misclassifier[49m[38;5;241m.[39msum()) [38;5;241m/[39m y[38;5;241m.[39msize,
[1;32m      4[0m ]
[1;32m      5[0m ensemble_weight

[0;31mNameError[0m: name 'mask_new_misclassifier' is not defined

